Workbook

Sheet Members
A1: ****************
A2: Member Database for BMX Ireland License DB
A3: Exported from Sqorz at Mon Mar 02 2026 14:36:58 GMT+0000 (Greenwich Mean Time)
A5: Required | B5: Required | C5: Required | D5: Required | E5: Required | F5: Required | G5: Required | H5: Required | I5: Optional | J5: Optional | K5: Optional | L5: Optional | M5: Optional | N5: Optional | O5: Optional | P5: Optional | Q5: Optional | R5: Optional | S5: Required | T5: Optional | U5: Optional | V5: Optional | W5: Optional | X5: Optional | Y5: Optional | Z5: Optional | AA5: Optional | AB5: Optional
C6: YYYY-MM-DD | F6: YYYY-MM-DD | G6: M/F | H6: Yes/No | M6: AA-NNNNN | N6: AA-NNNNN | O6: AA-NNNNN | P6: AA-NNNNN
A7: ****************
A8: License Number | B8: License Class | C8: License Expiry | D8: Given Name | E8: Family Name | F8: Birth Date | G8: Gender | H8: Active | I8: Plate 20 | J8: Plate 24 | K8: Plate Retro | L8: Plate Open | M8: Transponder 20 | N8: Transponder 24 | O8: Transponder Retro | P8: Transponder Open | Q8: License Country Code | R8: International License | S8: Club Name | T8: Team Name 1 | U8: Team Name 2 | V8: Team Name 3 | W8: Team Name 4 | X8: Team Name 5 | Y8: Email | Z8: CC Email | AA8: Emergency Contact Person | AB8: Emergency Contact Number
A9: 25LC0600 | B9: Adult | C9: 2025-12-31 | D9: Demelza | E9: FRANSSEN | F9: 1980-08-01 | G9: F | H9: Yes | I9: 914 | M9: FR-40459 | Q9: IRL | R9: 10133221501 | S9: Cork BMX
A10: LM-0303266 | B10: Adult | C10: 2025-12-31 | D10: RODNEY | E10: KENNEDY | F10: 1975-09-10 | G10: M | H10: Yes | I10: None | Q10: IRL | R10: 10116223461 | S10: Lisburn BMX
A11: LM-0315014 | B11: Adult | C11: 2025-12-31 | D11: Paul | E11: QUINN | F11: 1980-01-07 | G11: M | H11: Yes | I11: None | Q11: IRL | R11: 10143448836 | S11: Cork BMX
A12: 24LC1822 | B12: Adult | C12: 2024-12-31 | D12: Jonathan | E12: REID | F12: 1978-04-24 | G12: M | H12: Yes | Q12: IRL | R12: 10017085118 | S12: Belfast City BMX
A13: 25U80170 | B13: Youth | C13: 2025-12-31 | D13: Francesco | E13: PITINO | F13: 2018-12-14 | G13: M | H13: Yes | Q13: IRL | S13: Lucan BMX
A14: 24U23345 | B14: Youth | C14: 2024-12-31 | D14: Harlee | E14: GLYNN | F14: 2015-03-01 | G14: F | H14: Yes | I14: 497 | Q14: IRL | S14: Ratoath BMX
A15: LM-0316136 | B15: Adult | C15: 2025-12-31 | D15: Oliver | E15: COAKLEY | F15: 1977-03-08 | G15: M | H15: Yes | I15: None | Q15: IRL | R15: 10145228683 | S15: Cork BMX
A16: 25U80082 | B16: Youth | C16: 2025-12-31 | D16: Dáithí | E16: MIROWSKI | F16: 2018-04-14 | G16: M | H16: Yes | I16: 590 | Q16: IRL | S16: Cork BMX
A17: 25LC0017 | B17: Adult | C17: 2025-12-31 | D17: Eamonn | E17: WYER | F17: 1968-09-18 | G17: M | H17: Yes | I17: 34 | M17: FL-29533 | Q17: IRL | R17: 10017236880 | S17: Lucan BMX
A18: 24U80072 | B18: Youth | C18: 2024-12-31 | D18: William | E18: THOMPSON | F18: 2017-05-26 | G18: M | H18: Yes | I18: None | Q18: GBR | R18: 10143727207 | S18: Belfast City BMX
A19: 24U80094 | B19: Youth | C19: 2024-12-31 | D19: Katie | E19: BRERETON | F19: 2018-03-23 | G19: F | H19: Yes | I19: 553 | M19: HN-81931 | Q19: IRL | R19: 10136972973 | S19: Lucan BMX
A20: 23U80172 | B20: Youth | C20: 2023-12-31 | D20: Ollie | E20: WILSON | F20: 2017-01-01 | G20: M | H20: Yes | I20: 788 | M20: RG-15585 | Q20: IRL | R20: 10129535093 | S20: Belfast City BMX
A21: 23LC2318 | B21: Adult | C21: 2023-12-31 | D21: Geronimo | E21: ROA | F21: 1989-07-11 | G21: M | H21: Yes | I21: 126 | M21: TL-43056 | Q21: IRL | R21: 10005883234 | S21: Ratoath BMX
A22: LM-0239214 | B22: Adult | C22: 2025-12-31 | D22: Fiona | E22: CAMPBELL | F22: 1965-11-16 | G22: F | H22: Yes | I22: 888 | Q22: IRL | R22: 10088224211 | S22: Ratoath BMX
A23: LM-0306633 | B23: Adult | C23: 2022-12-31 | D23: Tom | E23: GORDON | F23: 1999-05-07 | G23: M | H23: Yes | I23: 987 | Q23: IRL | R23: 10122121566 | S23: Lisburn BMX
A24: LM-0317787 | B24: Adult | C24: 2025-12-31 | D24: Ivo | E24: VACLAVEK | F24: 1976-07-28 | G24: M | H24: Yes | I24: None | Q24: IRL | R24: 10148867702 | S24: Cork BMX
A25: 25LC1448 | B25: Adult | C25: 2025-12-31 | D25: Joseph | E25: O'NEILL | F25: 1981-06-18 | G25: M | H25: Yes | I25: 732 | M25: RF-38162 | N25: RF-38162 | Q25: IRL | R25: 10017188279 | S25: Saint Annes BMX
A26: 25U80083 | B26: Youth | C26: 2025-12-31 | D26: Aidan | E26: SUMNER | F26: 2017-03-16 | G26: M | H26: Yes | I26: None | Q26: IRL | R26: 10148784947 | S26: Cork BMX
A27: CS-0190248 | B27: Adult | C27: 2024-12-31 | D27: James | E27: MCNALLY | F27: 1967-05-02 | G27: M | H27: Yes | I27: 22 | M27: LZ-31160 | Q27: IRL | R27: 10017493225 | S27: Ratoath BMX
A28: 24U80150 | B28: Youth | C28: 2024-12-31 | D28: Aisling | E28: ELLIOTT | F28: 2016-02-06 | G28: F | H28: Yes | I28: 283 | M28: KS-61241 | Q28: IRL | R28: 10124954370 | S28: Cork BMX
A29: 25C30718 | B29: Youth | C29: 2025-12-31 | D29: Charlie | E29: JACKSON | F29: 2006-04-29 | G29: M | H29: Yes | I29: 194 | M29: NT-64531 | Q29: IRL | R29: 10016846052 | S29: Ratoath BMX
A30: 23LC2726 | B30: Adult | C30: 2023-12-31 | D30: Martina | E30: MASARIKOVA | F30: 1983-02-08 | G30: F | H30: Yes | I30: 825 | Q30: IRL | S30: Cork BMX
A31: 24U80095 | B31: Youth | C31: 2024-12-31 | D31: Leo | E31: STURGEON | F31: 2017-03-22 | G31: M | H31: Yes | I31: 725 | M31: FX-23650 | Q31: IRL | R31: 10123893737 | S31: Lisburn BMX
A32: 23U80052 | B32: Youth | C32: 2023-12-31 | D32: William | E32: WAUGH | F32: 2016-05-23 | G32: M | H32: Yes | I32: 946 | M32: SR-89207 | Q32: IRL | S32: Lisburn BMX
A33: 23U80173 | B33: Youth | C33: 2023-12-31 | D33: Nora | E33: MALONE | F33: 2015-07-13 | G33: F | H33: Yes | Q33: IRL | R33: 10129884802 | S33: Lisburn BMX
A34: 23U80294 | B34: Youth | C34: 2023-12-31 | D34: Alfie | E34: DUGGAN | F34: 2015-09-26 | G34: M | H34: Yes | I34: 777 | Q34: IRL | R34: 10142440541 | S34: Ratoath BMX
A35: 25LC0833 | B35: Adult | C35: 2025-12-31 | D35: Cyril | E35: MICHELLAND | F35: 1976-07-28 | G35: M | H35: Yes | I35: 955 | M35: FK-91414 | Q35: IRL | R35: 10110422659 | S35: Lucan BMX
A36: LM-0306832 | B36: Adult | C36: 2025-12-31 | D36: Gemma | E36: MCNAMARA | F36: 1980-11-13 | G36: F | H36: Yes | I36: None | Q36: GBR | R36: 10122862305 | S36: Belfast City BMX
A37: LM-0316886 | B37: Adult | C37: 2024-12-31 | D37: Dermott | E37: JEWELL | F37: 1990-01-02 | G37: M | H37: Yes | I37: None | Q37: IRL | R37: 10146843331 | S37: Lucan BMX
A38: 25U80040 | B38: Youth | C38: 2025-12-31 | D38: Finn | E38: ROBERTS | F38: 2018-03-05 | G38: M | H38: Yes | I38: 446 | Q38: IRL | S38: Lisburn BMX
A39: LM-0210890 | B39: Adult | C39: 2025-12-31 | D39: Lar | E39: MASSEY | F39: 1971-12-27 | G39: M | H39: Yes | I39: 15 | Q39: IRL | R39: 10017422901 | S39: Lucan BMX
A40: 25LC0239 | B40: Adult | C40: 2025-12-31 | D40: Steven | E40: MCCLEW | F40: 1967-08-09 | G40: M | H40: Yes | I40: 42 | M40: FK-68798 | Q40: IRL | R40: 10090103179 | S40: Cork BMX
A41: LM-0317249 | B41: Adult | C41: 2024-12-31 | D41: ANDREW | E41: MORROW | F41: 1979-04-28 | G41: M | H41: Yes | I41: None | Q41: IRL | R41: 10147514045 | S41: Lisburn BMX
...

Sheet Groups
A1: ****************
A2: Required | B2: Required | C2: Required | D2: Required | E2: Optional | F2: Optional | G2: Required for Teams | H2: Optional | I2: Optional
D3: Club/Team
A4: ****************
A5: Group ID | B5: Group Name | C5: Group Short Name | D5: Group Type | E5: State | F5: Country | G5: League Name 1 | H5: League Name 2 | I5: League Name 3
A6: 10 | B6: Belfast City BMX | C6: BCBMX | D6: Club | F6: Ireland
A7: 20 | B7: Cork BMX | C7: CRKBMX | D7: Club | F7: Ireland
A8: 30 | B8: Courtown BMX | C8: COURTN | D8: Club | F8: Ireland
A9: 40 | B9: East Coast Raiders BMX | C9: ECRBMX | D9: Club | F9: Ireland
A10: 50 | B10: Lisburn BMX | C10: LISBMX | D10: Club | F10: UK
A11: 60 | B11: Lucan BMX | C11: LUCBMX | D11: Club | F11: Ireland
A12: 90 | B12: Other | C12: OTHER | D12: Club | F12: Ireland
A13: 70 | B13: Ratoath BMX | C13: RATBMX | D13: Club | F13: Ireland
A14: 80 | B14: Saint Annes BMX | C14: STANBMX | D14: Club | F14: Ireland

Sheet Leagues
A1: ****************
A2: Required | B2: Required
A4: ****************
A5: League ID | B5: League Name

Sheet Validation
A1: ****************
A2: DO NOT MAKE CHANGES TO THIS WORKSHEET!
A3: This sheet is used to validate data entry on other sheets.
A4: ****************
A5: Clubs | B5: Teams | C5: License Classes
A6: =IF(Groups!D6="Club",Groups!B6,"") | B6: =IF(Groups!D6="Team",Groups!B6,"") | C6: Adult
A7: =IF(Groups!D7="Club",Groups!B7,"") | B7: =IF(Groups!D7="Team",Groups!B7,"") | C7: Youth
A8: =IF(Groups!D8="Club",Groups!B8,"") | B8: =IF(Groups!D8="Team",Groups!B8,"")
A9: =IF(Groups!D9="Club",Groups!B9,"") | B9: =IF(Groups!D9="Team",Groups!B9,"")
A10: =IF(Groups!D10="Club",Groups!B10,"") | B10: =IF(Groups!D10="Team",Groups!B10,"")
A11: =IF(Groups!D11="Club",Groups!B11,"") | B11: =IF(Groups!D11="Team",Groups!B11,"")
A12: =IF(Groups!D12="Club",Groups!B12,"") | B12: =IF(Groups!D12="Team",Groups!B12,"")
A13: =IF(Groups!D13="Club",Groups!B13,"") | B13: =IF(Groups!D13="Team",Groups!B13,"")
A14: =IF(Groups!D14="Club",Groups!B14,"") | B14: =IF(Groups!D14="Team",Groups!B14,"")
A15: =IF(Groups!D15="Club",Groups!B15,"") | B15: =IF(Groups!D15="Team",Groups!B15,"")
A16: =IF(Groups!D16="Club",Groups!B16,"") | B16: =IF(Groups!D16="Team",Groups!B16,"")
A17: =IF(Groups!D17="Club",Groups!B17,"") | B17: =IF(Groups!D17="Team",Groups!B17,"")
A18: =IF(Groups!D18="Club",Groups!B18,"") | B18: =IF(Groups!D18="Team",Groups!B18,"")
A19: =IF(Groups!D19="Club",Groups!B19,"") | B19: =IF(Groups!D19="Team",Groups!B19,"")
... A1005: =IF(Groups!D1005="Club",Groups!B1005,"") | B1005: =IF(Groups!D1005="Team",Groups!B1005,"")
